<?xml version='1.0' encoding='UTF-8'?>
<sdf version="1.6">
  <model name="auv3">
    <pose>0 0 0 0 0 0</pose>

    <!-- BlueROV2 thruster reference: http://www.ardusub.com/introduction/features.html -->
    <!-- fluid_density: 1000 -->
    <!-- displaced_mass: 10.05 -->

    <link name="base_link">
      <inertial>
        <pose>0 0 0.011 0 0 0</pose>
        <mass>10</mass>
        <inertia>
          <ixx>0.09873097998042396</ixx>
          <ixy>0</ixy>
          <ixz>0</ixz>
          <iyy>0.17756847998042397</iyy>
          <iyz>0</iyz>
          <izz>0.2692441666666667</izz>
        </inertia>
      </inertial>

      <visual name="base_link_visual">
        <geometry>
          <mesh>
            <uri>model://orca4/meshes/bluerov2.dae</uri>
            <scale>0.025 0.025 0.025</scale>
          </mesh>
        </geometry>
      </visual>

      <!-- Collision volume * fluid_density == displaced mass, used by BuoyancyPlugin -->
      <collision name="base_link_collision">
        <pose>0 0 0.06 0 0 0</pose>
        <geometry>
          <box>
            <size>0.457 0.338 0.06506286173008947</size>
          </box>
        </geometry>
      </collision>

      <!-- IMU sensor gyro and accel data will be sent to ArduSub -->
      <sensor name="imu_sensor" type="imu">
        <!-- Transform from the Gazebo body frame (x-forward, y-left, z-up)
             to the ArduPilot body frame (x-forward, y-right, z-down) -->
        <pose>0 0 0 3.141592653589793 0 0</pose>
        <always_on>1</always_on>
        <update_rate>1000.0</update_rate>
      </sensor>

    </link>

    <!-- Thruster 1 -->
    <link name="thruster1_link">
      <pose>-0.264 0.0775 0.01 0 1.5707963267948966 1.5707963267948966</pose>
      <visual name="thruster1_visual">
        <geometry>
          <mesh>
            <uri>model://orca4/meshes/t200-ccw-prop.dae</uri>
            <scale>0.01 0.01 0.01</scale>
          </mesh>
        </geometry>
      </visual>
      <inertial>
        <mass>0.001</mass>
        <inertia>
          <ixx>0.001</ixx>
          <ixy>0</ixy>
          <ixz>0</ixz>
          <iyy>0.001</iyy>
          <iyz>0</iyz>
          <izz>0.001</izz>
        </inertia>
      </inertial>
    </link>

    <joint name="thruster1_joint" type="revolute">
      <parent>base_link</parent>
      <child>thruster1_link</child>
      <axis>
        <xyz>1 0 0</xyz>
        <limit>
          <lower>-1e16</lower>
          <upper>1e16</upper>
        </limit>
        <dynamics>
          <spring_reference>0</spring_reference>
          <spring_stiffness>0</spring_stiffness>
        </dynamics>
        <use_parent_model_frame>1</use_parent_model_frame>
      </axis>
    </joint>

    <!-- Thruster 2 -->
    <link name="thruster2_link">
      <pose>-0.264 -0.0775 0.01 0 1.5707963267948966 4.71238898038469</pose>
      <visual name="thruster2_visual">
        <geometry>
          <mesh>
            <uri>model://orca4/meshes/t200-cw-prop.dae</uri>
            <scale>0.01 0.01 0.01</scale>
          </mesh>
        </geometry>
      </visual>
      <inertial>
        <mass>0.001</mass>
        <inertia>
          <ixx>0.001</ixx>
          <ixy>0</ixy>
          <ixz>0</ixz>
          <iyy>0.001</iyy>
          <iyz>0</iyz>
          <izz>0.001</izz>
        </inertia>
      </inertial>
    </link>

    <joint name="thruster2_joint" type="revolute">
      <parent>base_link</parent>
      <child>thruster2_link</child>
      <axis>
        <xyz>1 0 0</xyz>
        <limit>
          <lower>-1e16</lower>
          <upper>1e16</upper>
        </limit>
        <dynamics>
          <spring_reference>0</spring_reference>
          <spring_stiffness>0</spring_stiffness>
        </dynamics>
        <use_parent_model_frame>1</use_parent_model_frame>
      </axis>
    </joint>

    <!-- Thruster 3 -->
    <link name="thruster3_link">
      <pose>0.064 0.0775 0.01 0 1.5707963267948966 1.5707963267948966</pose>
      <visual name="thruster3_visual">
        <geometry>
          <mesh>
            <uri>model://orca4/meshes/t200-cw-prop.dae</uri>
            <scale>0.01 0.01 0.01</scale>
          </mesh>
        </geometry>
      </visual>
      <inertial>
        <mass>0.001</mass>
        <inertia>
          <ixx>0.001</ixx>
          <ixy>0</ixy>
          <ixz>0</ixz>
          <iyy>0.001</iyy>
          <iyz>0</iyz>
          <izz>0.001</izz>
        </inertia>
      </inertial>
    </link>

    <joint name="thruster3_joint" type="revolute">
      <parent>base_link</parent>
      <child>thruster3_link</child>
      <axis>
        <xyz>1 0 0</xyz>
        <limit>
          <lower>-1e16</lower>
          <upper>1e16</upper>
        </limit>
        <dynamics>
          <spring_reference>0</spring_reference>
          <spring_stiffness>0</spring_stiffness>
        </dynamics>
        <use_parent_model_frame>1</use_parent_model_frame>
      </axis>
    </joint>

    <!-- Thruster 4 -->
    <link name="thruster4_link">
      <pose>0.064 -0.0775 0.01 0 1.5707963267948966 4.71238898038469</pose>
      <visual name="thruster4_visual">
        <geometry>
          <mesh>
            <uri>model://orca4/meshes/t200-ccw-prop.dae</uri>
            <scale>0.01 0.01 0.01</scale>
          </mesh>
        </geometry>
      </visual>
      <inertial>
        <mass>0.001</mass>
        <inertia>
          <ixx>0.001</ixx>
          <ixy>0</ixy>
          <ixz>0</ixz>
          <iyy>0.001</iyy>
          <iyz>0</iyz>
          <izz>0.001</izz>
        </inertia>
      </inertial>
    </link>

    <joint name="thruster4_joint" type="revolute">
      <parent>base_link</parent>
      <child>thruster4_link</child>
      <axis>
        <xyz>1 0 0</xyz>
        <limit>
          <lower>-1e16</lower>
          <upper>1e16</upper>
        </limit>
        <dynamics>
          <spring_reference>0</spring_reference>
          <spring_stiffness>0</spring_stiffness>
        </dynamics>
        <use_parent_model_frame>1</use_parent_model_frame>
      </axis>
    </joint>

    <!-- Thruster 5 -->
    <link name="thruster5_link">
      <pose>-0.1 0.25175 0.01 0 0 1.5707963267948966</pose>
      <visual name="thruster5_visual">
        <geometry>
          <mesh>
            <uri>model://orca4/meshes/t200-ccw-prop.dae</uri>
            <scale>0.01 0.01 0.01</scale>
          </mesh>
        </geometry>
      </visual>
      <inertial>
        <mass>0.001</mass>
        <inertia>
          <ixx>0.001</ixx>
          <ixy>0</ixy>
          <ixz>0</ixz>
          <iyy>0.001</iyy>
          <iyz>0</iyz>
          <izz>0.001</izz>
        </inertia>
      </inertial>
    </link>

    <joint name="thruster5_joint" type="revolute">
      <parent>base_link</parent>
      <child>thruster5_link</child>
      <axis>
        <xyz>0 0 1</xyz>
        <limit>
          <lower>-1e16</lower>
          <upper>1e16</upper>
        </limit>
        <dynamics>
          <spring_reference>0</spring_reference>
          <spring_stiffness>0</spring_stiffness>
        </dynamics>
        <use_parent_model_frame>1</use_parent_model_frame>
      </axis>
    </joint>

    <!-- Thruster 6 -->
    <link name="thruster6_link">
      <pose>-0.1 -0.25175 0.01 0 0 4.71238898038469</pose>
      <visual name="thruster6_visual">
        <geometry>
          <mesh>
            <uri>model://orca4/meshes/t200-cw-prop.dae</uri>
            <scale>0.01 0.01 0.01</scale>
          </mesh>
        </geometry>
      </visual>
      <inertial>
        <mass>0.001</mass>
        <inertia>
          <ixx>0.001</ixx>
          <ixy>0</ixy>
          <ixz>0</ixz>
          <iyy>0.001</iyy>
          <iyz>0</iyz>
          <izz>0.001</izz>
        </inertia>
      </inertial>
    </link>

    <joint name="thruster6_joint" type="revolute">
      <parent>base_link</parent>
      <child>thruster6_link</child>
      <axis>
        <xyz>0 0 1</xyz>
        <limit>
          <lower>-1e16</lower>
          <upper>1e16</upper>
        </limit>
        <dynamics>
          <spring_reference>0</spring_reference>
          <spring_stiffness>0</spring_stiffness>
        </dynamics>
        <use_parent_model_frame>1</use_parent_model_frame>
      </axis>
    </joint>

    <!-- Thruster plugins -->
    <plugin
        filename="gz-sim-thruster-system"
        name="gz::sim::systems::Thruster">
      <namespace>auv3</namespace>
      <joint_name>thruster1_joint</joint_name>
      <thrust_coefficient>0.0167</thrust_coefficient>
      <fluid_density>1000</fluid_density>
      <propeller_diameter>0.1</propeller_diameter>
      <velocity_control>true</velocity_control>
      <use_angvel_cmd>False</use_angvel_cmd>
    </plugin>

    <plugin
        filename="gz-sim-thruster-system"
        name="gz::sim::systems::Thruster">
      <namespace>auv3</namespace>
      <joint_name>thruster2_joint</joint_name>
      <thrust_coefficient>0.0167</thrust_coefficient>
      <fluid_density>1000</fluid_density>
      <propeller_diameter>0.1</propeller_diameter>
      <velocity_control>true</velocity_control>
      <use_angvel_cmd>False</use_angvel_cmd>
    </plugin>

    <plugin
        filename="gz-sim-thruster-system"
        name="gz::sim::systems::Thruster">
      <namespace>auv3</namespace>
      <joint_name>thruster3_joint</joint_name>
      <thrust_coefficient>0.0167</thrust_coefficient>
      <fluid_density>1000</fluid_density>
      <propeller_diameter>0.1</propeller_diameter>
      <velocity_control>true</velocity_control>
      <use_angvel_cmd>False</use_angvel_cmd>
    </plugin>

    <plugin
        filename="gz-sim-thruster-system"
        name="gz::sim::systems::Thruster">
      <namespace>auv3</namespace>
      <joint_name>thruster4_joint</joint_name>
      <thrust_coefficient>0.0167</thrust_coefficient>
      <fluid_density>1000</fluid_density>
      <propeller_diameter>0.1</propeller_diameter>
      <velocity_control>true</velocity_control>
      <use_angvel_cmd>False</use_angvel_cmd>
    </plugin>

    <plugin
        filename="gz-sim-thruster-system"
        name="gz::sim::systems::Thruster">
      <namespace>auv3</namespace>
      <joint_name>thruster5_joint</joint_name>
      <thrust_coefficient>0.0167</thrust_coefficient>
      <fluid_density>1000</fluid_density>
      <propeller_diameter>0.1</propeller_diameter>
      <velocity_control>true</velocity_control>
      <use_angvel_cmd>False</use_angvel_cmd>
    </plugin>

    <plugin
        filename="gz-sim-thruster-system"
        name="gz::sim::systems::Thruster">
      <namespace>auv3</namespace>
      <joint_name>thruster6_joint</joint_name>
      <thrust_coefficient>0.0167</thrust_coefficient>
      <fluid_density>1000</fluid_density>
      <propeller_diameter>0.1</propeller_diameter>
      <velocity_control>true</velocity_control>
      <use_angvel_cmd>False</use_angvel_cmd>
    </plugin>

    <plugin name="ArduPilotPlugin" filename="libArduPilotPlugin.so">
      <!-- Port settings for AUV3 (I2) -->
      <fdm_addr>127.0.0.1</fdm_addr>
      <fdm_port_in>9022</fdm_port_in>
      <connectionTimeoutMaxCount>5</connectionTimeoutMaxCount>
      <lock_step>1</lock_step>

      <!-- Transform from the Gazebo body frame (x-forward, y-left, z-up)
           to the ArduPilot body frame (x-forward, y-right, z-down) -->
      <modelXYZToAirplaneXForwardZDown>0 0 0 3.141592653589793 0 0</modelXYZToAirplaneXForwardZDown>

      <!-- Transform from the Gazebo world frame (ENU)
           to the ArduPilot world frame (NED) -->
      <gazeboXYZToNED>0 0 0 3.141592653589793 0 1.5707963267948966</gazeboXYZToNED>

      <!-- Sensors -->
      <imuName>imu_sensor</imuName>

      <!-- Thrusters -->
      <control channel="0">
        <jointName>thruster1_joint</jointName>
        <servo_min>1100</servo_min>
        <servo_max>1900</servo_max>
        <type>COMMAND</type>
        <cmd_topic>/model/auv3/joint/thruster1_joint/cmd_thrust</cmd_topic>
        <offset>-0.5</offset>
        <multiplier>100</multiplier>
      </control>
      <control channel="1">
        <jointName>thruster2_joint</jointName>
        <servo_min>1100</servo_min>
        <servo_max>1900</servo_max>
        <type>COMMAND</type>
        <cmd_topic>/model/auv3/joint/thruster2_joint/cmd_thrust</cmd_topic>
        <offset>-0.5</offset>
        <multiplier>100</multiplier>
      </control>
      <control channel="2">
        <jointName>thruster3_joint</jointName>
        <servo_min>1100</servo_min>
        <servo_max>1900</servo_max>
        <type>COMMAND</type>
        <cmd_topic>/model/auv3/joint/thruster3_joint/cmd_thrust</cmd_topic>
        <offset>-0.5</offset>
        <multiplier>100</multiplier>
      </control>
      <control channel="3">
        <jointName>thruster4_joint</jointName>
        <servo_min>1100</servo_min>
        <servo_max>1900</servo_max>
        <type>COMMAND</type>
        <cmd_topic>/model/auv3/joint/thruster4_joint/cmd_thrust</cmd_topic>
        <offset>-0.5</offset>
        <multiplier>100</multiplier>
      </control>
      <control channel="4">
        <jointName>thruster5_joint</jointName>
        <servo_min>1100</servo_min>
        <servo_max>1900</servo_max>
        <type>COMMAND</type>
        <cmd_topic>/model/auv3/joint/thruster5_joint/cmd_thrust</cmd_topic>
        <offset>-0.5</offset>
        <multiplier>100</multiplier>
      </control>
      <control channel="5">
        <jointName>thruster6_joint</jointName>
        <servo_min>1100</servo_min>
        <servo_max>1900</servo_max>
        <type>COMMAND</type>
        <cmd_topic>/model/auv3/joint/thruster6_joint/cmd_thrust</cmd_topic>
        <offset>-0.5</offset>
        <multiplier>100</multiplier>
      </control>

    </plugin>

    <!-- Left camera link -->
    <link name="left_camera_link">
      <pose>-0.18 0.18 -0.06749999999999999 0 0 0</pose>
      <visual name="left_camera_tube">
        <transparency>0.5</transparency>
        <geometry>
          <cylinder>
            <length>0.135</length>
            <radius>0.0275</radius>
          </cylinder>
        </geometry>
      </visual>
      <sensor name="left_camera" type="camera">
        <pose>0 0 -0.08750000000000001 0 1.5707963267948966 0</pose>
        <camera>
          <horizontal_fov>1.4</horizontal_fov>
          <image>
            <width>800</width>
            <height>600</height>
          </image>
          <clip>
            <near>0.2</near>
            <far>4</far>
          </clip>
        </camera>
        <always_on>1</always_on>
        <update_rate>5</update_rate>
        <visualize>true</visualize>
        <topic>auv3/stereo_left</topic>
      </sensor>
      <inertial>
        <mass>0.001</mass>
        <inertia>
          <ixx>0.001</ixx>
          <ixy>0</ixy>
          <ixz>0</ixz>
          <iyy>0.001</iyy>
          <iyz>0</iyz>
          <izz>0.001</izz>
        </inertia>
      </inertial>
    </link>

    <!-- Attach left_camera_link to base_link -->
    <joint name="left_camera_joint" type="fixed">
      <parent>base_link</parent>
      <child>left_camera_link</child>
    </joint>

    <!-- Right camera link -->
    <link name="right_camera_link">
      <pose>-0.18 -0.18 -0.06749999999999999 0 0 0</pose>
      <visual name="right_camera_tube">
        <transparency>0.5</transparency>
        <geometry>
          <cylinder>
            <length>0.135</length>
            <radius>0.0275</radius>
          </cylinder>
        </geometry>
      </visual>
      <sensor name="right_camera" type="camera">
        <pose>0 0 -0.08750000000000001 0 1.5707963267948966 0</pose>
        <camera>
          <horizontal_fov>1.4</horizontal_fov>
          <image>
            <width>800</width>
            <height>600</height>
          </image>
          <clip>
            <near>0.2</near>
            <far>4</far>
          </clip>
        </camera>
        <always_on>1</always_on>
        <update_rate>5</update_rate>
        <visualize>true</visualize>
        <topic>auv3/stereo_right</topic>
      </sensor>
      <inertial>
        <mass>0.001</mass>
        <inertia>
          <ixx>0.001</ixx>
          <ixy>0</ixy>
          <ixz>0</ixz>
          <iyy>0.001</iyy>
          <iyz>0</iyz>
          <izz>0.001</izz>
        </inertia>
      </inertial>
    </link>

    <!-- Attach right_camera_link to base_link -->
    <joint name="right_camera_joint" type="fixed">
      <parent>base_link</parent>
      <child>right_camera_link</child>
    </joint>

    <!-- Publish the ground-truth pose for rviz -->
    <plugin
        filename="gz-sim-odometry-publisher-system"
        name="gz::sim::systems::OdometryPublisher">
      <odom_frame>map</odom_frame>
      <robot_base_frame>auv3</robot_base_frame>
      <dimensions>3</dimensions>
    </plugin>

  </model>
</sdf>
